<?xml version="1.0" encoding="utf-8"?>
<!-- This URDF was automatically created by SolidWorks to URDF Exporter! Originally created by Stephen Brawner (brawner@gmail.com) 
     Commit Version: 1.6.0-4-g7f85cfe  Build Version: 1.6.7995.38578
     For more information, please see http://wiki.ros.org/sw_urdf_exporter -->
<robot
  name="PFR_Arm2">
  <link
    name="world" />
  <joint
    name="world_to_base"
    type="floating">
    <origin
      xyz="0 0 0"
      rpy="0 0 0" />
    <parent
      link="world" />
    <child
      link="base_link" />
  </joint>
  <link
    name="base_link">
  <inertial>
    <origin
      xyz="2.67023784161503E-17 1.38748955932851E-17 0.185886916570362"
      rpy="0 0 0" />

    <mass
      value="9.4" />

    <inertia
      ixx="0.184014"
      ixy="-4.733E-14"
      ixz="-1.276E-18"
      iyy="0.183998"
      iyz="9.548E-22"
      izz="0.153096" />
  </inertial>
    <visual>
      <origin
        xyz="0 0 0"
        rpy="0 0 0" />
      <geometry>
        <mesh
          filename="package://PFR_Arm2/meshes/base_link.STL" />
      </geometry>
      <material
        name="">
        <color
          rgba="0.792156862745098 0.819607843137255 0.933333333333333 1" />
      </material>
    </visual>
    <collision>
      <origin
        xyz="0 0 0"
        rpy="0 0 0" />
      <geometry>
        <mesh
          filename="package://PFR_Arm2/meshes/base_link.STL" />
      </geometry>
    </collision>
  </link>
  <link
    name="joint1_R">
<inertial>
  <origin
    xyz="-9.31857326154312E-11 -0.195378541069816 0.00672546665364099"
    rpy="0 0 0" />
  <mass
    value="0.610933607210843" />
  <inertia
    ixx="0.002606149973"
    ixy="-8.759503414E-12"
    ixz="2.079170554E-12"
    iyy="0.000290799751"
    iyz="2.796985513E-05"
    izz="0.002521988319" />
</inertial>
    <visual>
      <origin
        xyz="0 0 0"
        rpy="0 0 0" />
      <geometry>
        <mesh
          filename="package://PFR_Arm2/meshes/Joint1_R.STL" />
      </geometry>
      <material
        name="">
        <color
          rgba="0.792156862745098 0.819607843137255 0.933333333333333 1" />
      </material>
    </visual>
    <collision>
      <origin
        xyz="0 0 0"
        rpy="0 0 0" />
      <geometry>
        <mesh
          filename="package://PFR_Arm2/meshes/Joint1_R.STL" />
      </geometry>
    </collision>
  </link>
  <joint
    name="joint1_R"
    type="revolute">
    <origin
      xyz="0 -0.18175 0.174"
      rpy="0 0 0" />
    <parent
      link="base_link" />
    <child
      link="joint1_R" />
    <axis
      xyz="0 0 -1" />
    <limit
      lower="-1.57079632679"
      upper="1.57079632679"
      effort="10"
      velocity="10" />
    <dynamics
      damping="0.02" />
  </joint>
  <link
    name="joint2_R">
  <inertial>
    <origin
      xyz="-8.81578836366647E-10 -0.205753132187302 0.00699863753540647"
      rpy="0 0 0" />
    <mass
      value="0.524093067317941" />
    <inertia
      ixx="0.002262706481047"
      ixy="5.393149924E-11"
      ixz="1.328143582E-11"
      iyy="0.000266808394608"
      iyz="-5.951057304E-06"
      izz="0.002161333435478" />
  </inertial>
    <visual>
      <origin
        xyz="0 0 0"
        rpy="0 0 0" />
      <geometry>
        <mesh
          filename="package://PFR_Arm2/meshes/Joint2_R.STL" />
      </geometry>
      <material
        name="">
        <color
          rgba="0.792156862745098 0.819607843137255 0.933333333333333 1" />
      </material>
    </visual>
    <collision>
      <origin
        xyz="0 0 0"
        rpy="0 0 0" />
      <geometry>
        <mesh
          filename="package://PFR_Arm2/meshes/Joint2_R.STL" />
      </geometry>
    </collision>
  </link>
  <joint
    name="joint2_R"
    type="revolute">
    <origin
      xyz="0 -0.3 0.00950000000000006"
      rpy="0 0 0" />
    <parent
      link="joint1_R" />
    <child
      link="joint2_R" />
    <axis
      xyz="0 0 -1" />
    <limit
      lower="-2.61799387799"
      upper="2.61799387799"
      effort="10"
      velocity="10" />
    <dynamics
      damping="0.02" />
  </joint>
  <link
    name="joint3_R">
  <inertial>
    <origin
      xyz="7.37750807914593E-05 0.0311442464401742 0.00549599281689406"
      rpy="0 0 0" />
    <mass
      value="0.2882871164231278" />
    <inertia
      ixx="1.1973444596E-04"
      ixy="-1.6349251489E-07"
      ixz="-3.6097973354E-07"
      iyy="1.3130622303E-04"
      iyz="4.3006438864E-06"
      izz="5.3818913752E-05" />
  </inertial>
    <visual>
      <origin
        xyz="0 0 0"
        rpy="0 0 0" />
      <geometry>
        <mesh
          filename="package://PFR_Arm2/meshes/Joint3_R.STL" />
      </geometry>
      <material
        name="">
        <color
          rgba="0.792156862745098 0.819607843137255 0.933333333333333 1" />
      </material>
    </visual>
    <collision>
      <origin
        xyz="0 0 0"
        rpy="0 0 0" />
      <geometry>
        <mesh
          filename="package://PFR_Arm2/meshes/Joint3_R.STL" />
      </geometry>
    </collision>
  </link>
  <joint
    name="joint3_R"
    type="revolute">
    <origin
      xyz="0 -0.3 0.00949999999999965"
      rpy="0 0 0" />
    <parent
      link="joint2_R" />
    <child
      link="joint3_R" />
    <axis
      xyz="0 0 -1" />
    <limit
      lower="-1.57079632679"
      upper="1.57079632679"
      effort="10"
      velocity="10" />
    <dynamics
      damping="0.02" />
  </joint>
  <link
    name="joint1_L">
  <inertial>
    <origin
      xyz="-9.31857326154312E-11 -0.195378541069816 0.00672546665364099"
      rpy="0 0 0" />
    <mass
      value="0.610933607210843" />
    <inertia
      ixx="0.002606149973"
      ixy="-8.759503414E-12"
      ixz="2.079170554E-12"
      iyy="0.000290799751"
      iyz="2.796985513E-05"
      izz="0.002521988319" />
  </inertial>
    <visual>
      <origin
        xyz="0 0 0"
        rpy="0 0 0" />
      <geometry>
        <mesh
          filename="package://PFR_Arm2/meshes/Joint1_L.STL" />
      </geometry>
      <material
        name="">
        <color
          rgba="0.792156862745098 0.819607843137255 0.933333333333333 1" />
      </material>
    </visual>
    <collision>
      <origin
        xyz="0 0 0"
        rpy="0 0 0" />
      <geometry>
        <mesh
          filename="package://PFR_Arm2/meshes/Joint1_L.STL" />
      </geometry>
    </collision>
  </link>
  <joint
    name="joint1_L"
    type="revolute">
    <origin
      xyz="0 0.18175 0.174"
      rpy="0 0 0" />
    <parent
      link="base_link" />
    <child
      link="joint1_L" />
    <axis
      xyz="0 0 1" />
    <limit
      lower="-1.57079632679"
      upper="1.57079632679"
      effort="10"
      velocity="10" />
    <dynamics
      damping="0.02" />
  </joint>
  <link
    name="joint2_L">
    <inertial>
      <origin
        xyz="-8.81578836366647E-10 -0.205753132187302 0.00699863753540647"
        rpy="0 0 0" />
      <mass
        value="0.524093067317941" />
      <inertia
        ixx="0.002262706481047"
        ixy="5.393149924E-11"
        ixz="1.328143582E-11"
        iyy="0.000266808394608"
        iyz="-5.951057304E-06"
        izz="0.002161333435478" />
    </inertial>
    <visual>
      <origin
        xyz="0 0 0"
        rpy="0 0 0" />
      <geometry>
        <mesh
          filename="package://PFR_Arm2/meshes/Joint2_L.STL" />
      </geometry>
      <material
        name="">
        <color
          rgba="0.792156862745098 0.819607843137255 0.933333333333333 1" />
      </material>
    </visual>
    <collision>
      <origin
        xyz="0 0 0"
        rpy="0 0 0" />
      <geometry>
        <mesh
          filename="package://PFR_Arm2/meshes/Joint2_L.STL" />
      </geometry>
    </collision>
  </link>
  <joint
    name="joint2_L"
    type="revolute">
    <origin
      xyz="0 0.3 0.00950000000000006"
      rpy="0 0 0" />
    <parent
      link="joint1_L" />
    <child
      link="joint2_L" />
    <axis
      xyz="0 0 1" />
    <limit
      lower="-2.61799387799"
      upper="2.61799387799"
      effort="10"
      velocity="10" />
    <dynamics
      damping="0.02" />
  </joint>
  <link
    name="joint3_L">
  <inertial>
    <origin
      xyz="7.37750807914593E-05 0.0311442464401742 0.00549599281689406"
      rpy="0 0 0" />
    <mass
      value="0.2882871164231278" />
    <inertia
      ixx="1.1973444596E-04"
      ixy="-1.6349251489E-07"
      ixz="-3.6097973354E-07"
      iyy="1.3130622303E-04"
      iyz="4.3006438864E-06"
      izz="5.3818913752E-05" />
  </inertial>
    <visual>
      <origin
        xyz="0 0 0"
        rpy="0 0 0" />
      <geometry>
        <mesh
          filename="package://PFR_Arm2/meshes/Joint3_L.STL" />
      </geometry>
      <material
        name="">
        <color
          rgba="0.776470588235294 0.756862745098039 0.737254901960784 1" />
      </material>
    </visual>
    <collision>
      <origin
        xyz="0 0 0"
        rpy="0 0 0" />
      <geometry>
        <mesh
          filename="package://PFR_Arm2/meshes/Joint3_L.STL" />
      </geometry>
    </collision>
  </link>
  <joint
    name="joint3_L"
    type="revolute">
    <origin
      xyz="0 0.3 0.00949999999999965"
      rpy="0 0 0" />
    <parent
      link="joint2_L" />
    <child
      link="joint3_L" />
    <axis
      xyz="0 0 1" />
    <limit
      lower="-1.57079632679"
      upper="1.57079632679"
      effort="10"
      velocity="10" />
    <dynamics
      damping="0.02" />
  </joint>

  <!-- Right-arm Dynamixel hardware interfaces.  The same robot description is
       consumed by ros2_control, robot_state_publisher, and Pinocchio. -->
  <ros2_control name="dxl_system" type="system">
    <hardware>
      <plugin>dynamixel_hardware_interface/DynamixelHardware</plugin>

      <param name="port_name">/dev/ttyUSB0</param>
      <param name="baud_rate">1000000</param>
      <param name="error_timeout_ms">250</param>
      <param name="dynamixel_model_folder">/param/dxl_model</param>
      <param name="disable_torque_at_init">true</param>

      <param name="dynamixel_state_pub_msg_name">/dynamixel_hardware_interface/dxl_state</param>
      <param name="get_dynamixel_data_srv_name">/dynamixel_hardware_interface/get_dxl_data</param>
      <param name="set_dynamixel_data_srv_name">/dynamixel_hardware_interface/set_dxl_data</param>
      <param name="reboot_dxl_srv_name">/dynamixel_hardware_interface/reboot_dxl</param>
      <param name="set_dxl_torque_srv_name">/dynamixel_hardware_interface/set_dxl_torque</param>

      <param name="number_of_joints">3</param>
      <param name="number_of_transmissions">3</param>
      <param name="transmission_to_joint_matrix">1, 0, 0, 0, 1, 0, 0, 0, 1</param>
      <param name="joint_to_transmission_matrix">1, 0, 0, 0, 1, 0, 0, 0, 1</param>
    </hardware>

    <joint name="joint1_R">
      <command_interface name="velocity" />
      <state_interface name="position" />
      <state_interface name="velocity" />
      <state_interface name="effort" />
    </joint>
    <joint name="joint2_R">
      <command_interface name="velocity" />
      <state_interface name="position" />
      <state_interface name="velocity" />
      <state_interface name="effort" />
    </joint>
    <joint name="joint3_R">
      <command_interface name="velocity" />
      <state_interface name="position" />
      <state_interface name="velocity" />
      <state_interface name="effort" />
    </joint>

    <gpio name="dxl1">
      <param name="type">dxl</param>
      <param name="ID">1</param>
      <param name="Operating Mode">1</param>
      <command_interface name="Goal Velocity" />
      <state_interface name="Present Position" />
      <state_interface name="Present Velocity" />
      <state_interface name="Present Current" />
    </gpio>
    <gpio name="dxl2">
      <param name="type">dxl</param>
      <param name="ID">2</param>
      <param name="Operating Mode">1</param>
      <command_interface name="Goal Velocity" />
      <state_interface name="Present Position" />
      <state_interface name="Present Velocity" />
      <state_interface name="Present Current" />
    </gpio>
    <gpio name="dxl3">
      <param name="type">dxl</param>
      <param name="ID">3</param>
      <param name="Operating Mode">1</param>
      <command_interface name="Goal Velocity" />
      <state_interface name="Present Position" />
      <state_interface name="Present Velocity" />
      <state_interface name="Present Current" />
    </gpio>
  </ros2_control>
</robot>
